[2021-03-28 19:25:46] INFO login  Api Service  Started
[2021-03-28 19:25:52] INFO Login ended....
[2021-03-28 19:25:52] INFO {'status': False, 'data': {'message': 'Something went wrong.'}}
[2021-03-28 19:25:52] ERROR 'bool' object has no attribute 'get'
[2021-03-28 19:25:52] ERROR Exception raised in Login as 'bool' object has no attribute 'get'
Traceback (most recent call last):
  File "G:\Care24\cms_backend\cms\helpers.py", line 31, in login
    serialized_data["token"] = auth_token.get("token", None)
AttributeError: 'bool' object has no attribute 'get'
[2021-03-28 19:27:35] INFO login  Api Service  Started
[2021-03-28 19:27:41] INFO Login ended....
[2021-03-28 19:27:41] INFO {'status': False, 'data': {'message': 'Something went wrong.'}}
[2021-03-28 19:27:41] ERROR 'bool' object has no attribute 'get'
[2021-03-28 19:27:41] ERROR Exception raised in Login as 'bool' object has no attribute 'get'
Traceback (most recent call last):
  File "G:\Care24\cms_backend\cms\helpers.py", line 31, in login
    serialized_data["token"] = auth_token.get("token", None)
AttributeError: 'bool' object has no attribute 'get'
[2021-03-28 19:28:25] INFO login  Api Service  Started
[2021-03-28 19:28:31] INFO Login ended....
[2021-03-28 19:28:31] INFO {'status': False, 'data': {'message': 'Something went wrong.'}}
[2021-03-28 19:28:31] ERROR 'bool' object has no attribute 'get'
[2021-03-28 19:28:31] ERROR Exception raised in Login as 'bool' object has no attribute 'get'
Traceback (most recent call last):
  File "G:\Care24\cms_backend\cms\helpers.py", line 32, in login
    serialized_data["token"] = auth_token.get("token", None)
AttributeError: 'bool' object has no attribute 'get'
[2021-03-28 19:33:57] INFO Registration  Api Service  Started
[2021-03-28 19:33:57] INFO Registration ended....
[2021-03-28 19:33:57] INFO {'status': True, 'data': {'message': 'User registered successfully.', 'status_code': 15}}
[2021-03-28 19:35:06] INFO login  Api Service  Started
[2021-03-28 19:35:13] INFO Login ended....
[2021-03-28 19:35:13] INFO {'status': False, 'data': {'message': 'Something went wrong.'}}
[2021-03-28 19:35:13] ERROR 'bool' object has no attribute 'get'
[2021-03-28 19:35:13] ERROR Exception raised in Login as 'bool' object has no attribute 'get'
Traceback (most recent call last):
  File "G:\Care24\cms_backend\cms\helpers.py", line 32, in login
    serialized_data["token"] = auth_token.get("token", None)
AttributeError: 'bool' object has no attribute 'get'
[2021-03-28 19:36:44] INFO login  Api Service  Started
[2021-03-28 19:36:45] INFO Login ended....
[2021-03-28 19:36:45] INFO {'success': True, 'data': {'user_id': 1, 'role_type': 'user', 'email_id': 'test@gmail.com', 'full_name': 'test', 'token': 'a22e5a01a943cc342ad5c6a2ae4c19cc8bca34fb'}}
[2021-03-28 19:40:25] INFO ListContent  Api Service  Started
[2021-03-28 19:40:25] INFO List Content ended....
[2021-03-28 19:40:25] INFO {'success': True, 'data': []}
[2021-03-28 19:40:30] INFO ListContent  Api Service  Started
[2021-03-28 19:40:30] INFO List Content ended....
[2021-03-28 19:40:30] INFO {'success': True, 'data': []}
[2021-03-28 19:40:46] INFO ListContent  Api Service  Started
[2021-03-28 19:40:46] INFO List Content ended....
[2021-03-28 19:40:46] INFO {'success': True, 'data': []}
[2021-03-28 19:41:45] INFO AddContent  Api Service  Started
[2021-03-28 19:41:45] INFO Add Content ended....
[2021-03-28 19:41:45] INFO {'status': False, 'data': {'message': 'data saved successfully'}}
[2021-03-28 19:42:22] INFO AddContent  Api Service  Started
[2021-03-28 19:42:22] INFO Add Content ended....
[2021-03-28 19:42:22] INFO {'status': True, 'data': {'message': 'data saved successfully'}}
[2021-03-28 19:42:49] INFO ListContent  Api Service  Started
[2021-03-28 19:42:49] INFO List Content ended....
[2021-03-28 19:42:49] INFO {'success': True, 'data': [OrderedDict([('content_id', 1), ('title', 'title1'), ('body', 'body1'), ('summary', 'summary1'), ('pdf_document_path', 'files/1_20210328-194145.pdf'), ('categories', 'blog_writer')]), OrderedDict([('content_id', 2), ('title', 'title2'), ('body', 'body2'), ('summary', 'summary2'), ('pdf_document_path', 'files/2_20210328-194222.pdf'), ('categories', 'blog_writer')])]}
[2021-03-28 19:43:23] INFO ListContent  Api Service  Started
[2021-03-28 19:43:23] ERROR name 'Q' is not defined
[2021-03-28 19:43:23] ERROR Exception raised in List Content as name 'Q' is not defined
Traceback (most recent call last):
  File "G:\Care24\cms_backend\cms\helpers.py", line 143, in list_content
    users_content_list = UsersContentSerializer.list(self, request_data)
  File "G:\Care24\cms_backend\cms\serializers.py", line 175, in list
    entry_query = helpers.get_query(value.get("search"), [
  File "G:\Care24\cms_backend\cms\helpers.py", line 59, in get_query
    q = Q(**{"%s__icontains" % field_name: term})
NameError: name 'Q' is not defined
[2021-03-28 19:44:41] INFO ListContent  Api Service  Started
[2021-03-28 19:44:41] INFO List Content ended....
[2021-03-28 19:44:41] INFO {'success': True, 'data': [OrderedDict([('content_id', 1), ('title', 'title1'), ('body', 'body1'), ('summary', 'summary1'), ('pdf_document_path', 'files/1_20210328-194145.pdf'), ('categories', 'blog_writer')]), OrderedDict([('content_id', 2), ('title', 'title2'), ('body', 'body2'), ('summary', 'summary2'), ('pdf_document_path', 'files/2_20210328-194222.pdf'), ('categories', 'blog_writer')])]}
[2021-03-28 19:44:49] INFO ListContent  Api Service  Started
[2021-03-28 19:44:49] INFO List Content ended....
[2021-03-28 19:44:49] INFO {'success': True, 'data': []}
[2021-03-28 19:46:15] INFO ListContent  Api Service  Started
[2021-03-28 19:46:15] INFO List Content ended....
[2021-03-28 19:46:15] INFO {'success': True, 'data': [OrderedDict([('content_id', 1), ('title', 'title1'), ('body', 'body1'), ('summary', 'summary1'), ('pdf_document_path', 'files/1_20210328-194145.pdf'), ('categories', 'blog_writer')]), OrderedDict([('content_id', 2), ('title', 'title2'), ('body', 'body2'), ('summary', 'summary2'), ('pdf_document_path', 'files/2_20210328-194222.pdf'), ('categories', 'blog_writer')])]}
[2021-03-28 19:46:18] INFO ListContent  Api Service  Started
[2021-03-28 19:46:18] INFO List Content ended....
[2021-03-28 19:46:18] INFO {'status': False, 'data': {'message': 'data not found'}}
[2021-03-28 19:46:25] INFO ListContent  Api Service  Started
[2021-03-28 19:46:25] INFO List Content ended....
[2021-03-28 19:46:25] INFO {'success': True, 'data': [OrderedDict([('content_id', 1), ('title', 'title1'), ('body', 'body1'), ('summary', 'summary1'), ('pdf_document_path', 'files/1_20210328-194145.pdf'), ('categories', 'blog_writer')]), OrderedDict([('content_id', 2), ('title', 'title2'), ('body', 'body2'), ('summary', 'summary2'), ('pdf_document_path', 'files/2_20210328-194222.pdf'), ('categories', 'blog_writer')])]}
[2021-03-28 19:48:36] INFO Registration  Api Service  Started
[2021-03-28 19:48:36] INFO Update Content ended....
[2021-03-28 19:48:36] INFO {'status': True, 'data': {'message': 'data saved successfully'}}
[2021-03-28 19:49:36] INFO Registration  Api Service  Started
[2021-03-28 19:49:36] INFO Update Content ended....
[2021-03-28 19:49:36] INFO {'status': True, 'data': {'message': 'data updated successfully'}}
[2021-03-28 19:49:58] INFO ListContent  Api Service  Started
[2021-03-28 19:49:58] INFO List Content ended....
[2021-03-28 19:49:58] INFO {'success': True, 'data': [OrderedDict([('content_id', 1), ('title', "('title3',)"), ('body', "('body3',)"), ('summary', "('summary3',)"), ('pdf_document_path', 'files/1_20210328-194936.pdf'), ('categories', 'blog_writer')]), OrderedDict([('content_id', 2), ('title', 'title2'), ('body', 'body2'), ('summary', 'summary2'), ('pdf_document_path', 'files/2_20210328-194222.pdf'), ('categories', 'blog_writer')])]}
[2021-03-28 19:50:51] INFO Registration  Api Service  Started
[2021-03-28 19:50:51] INFO Update Content ended....
[2021-03-28 19:50:51] INFO {'status': True, 'data': {'message': 'data updated successfully'}}
[2021-03-28 19:51:01] INFO ListContent  Api Service  Started
[2021-03-28 19:51:01] INFO List Content ended....
[2021-03-28 19:51:01] INFO {'success': True, 'data': [OrderedDict([('content_id', 1), ('title', "('title3',)"), ('body', "('body3',)"), ('summary', "('summary3',)"), ('pdf_document_path', 'files/1_20210328-195051.pdf'), ('categories', 'blog_writer')]), OrderedDict([('content_id', 2), ('title', 'title2'), ('body', 'body2'), ('summary', 'summary2'), ('pdf_document_path', 'files/2_20210328-194222.pdf'), ('categories', 'blog_writer')])]}
[2021-03-28 19:51:30] INFO ListContent  Api Service  Started
[2021-03-28 19:51:30] INFO List Content ended....
[2021-03-28 19:51:30] INFO {'success': True, 'data': [OrderedDict([('content_id', 1), ('title', "('title3',)"), ('body', "('body3',)"), ('summary', "('summary3',)"), ('pdf_document_path', 'files/1_20210328-195051.pdf'), ('categories', 'blog_writer')]), OrderedDict([('content_id', 2), ('title', 'title2'), ('body', 'body2'), ('summary', 'summary2'), ('pdf_document_path', 'files/2_20210328-194222.pdf'), ('categories', 'blog_writer')])]}
[2021-03-28 19:51:44] INFO AddContent  Api Service  Started
[2021-03-28 19:51:44] INFO Add Content ended....
[2021-03-28 19:51:44] INFO {'status': True, 'data': {'message': 'data saved successfully'}}
[2021-03-28 19:51:48] INFO Registration  Api Service  Started
[2021-03-28 19:51:48] INFO Update Content ended....
[2021-03-28 19:51:48] INFO {'status': True, 'data': {'message': 'data updated successfully'}}
[2021-03-28 19:51:56] INFO Registration  Api Service  Started
[2021-03-28 19:51:56] INFO Update Content ended....
[2021-03-28 19:51:56] INFO {'status': True, 'data': {'message': 'data updated successfully'}}
[2021-03-28 19:52:16] INFO Registration  Api Service  Started
[2021-03-28 19:52:16] INFO Update Content ended....
[2021-03-28 19:52:16] INFO {'status': True, 'data': {'message': 'data updated successfully'}}
[2021-03-28 19:52:31] INFO Registration  Api Service  Started
[2021-03-28 19:52:31] INFO Update Content ended....
[2021-03-28 19:52:31] INFO {'status': True, 'data': {'message': 'data updated successfully'}}
[2021-03-28 19:52:36] INFO ListContent  Api Service  Started
[2021-03-28 19:52:36] INFO List Content ended....
[2021-03-28 19:52:36] INFO {'success': True, 'data': [OrderedDict([('content_id', 1), ('title', "('title111',)"), ('body', "('body111',)"), ('summary', "('summary111',)"), ('pdf_document_path', 'files/1_20210328-195231.pdf'), ('categories', 'blog_writer')]), OrderedDict([('content_id', 2), ('title', 'title2'), ('body', 'body2'), ('summary', 'summary2'), ('pdf_document_path', 'files/2_20210328-194222.pdf'), ('categories', 'blog_writer')]), OrderedDict([('content_id', 3), ('title', 'title2'), ('body', 'body2'), ('summary', 'summary2'), ('pdf_document_path', 'files/3_20210328-195144.pdf'), ('categories', 'blog_writer')])]}
[2021-03-28 19:53:53] INFO Registration  Api Service  Started
[2021-03-28 19:53:53] INFO Update Content ended....
[2021-03-28 19:53:53] INFO {'status': True, 'data': {'message': 'data updated successfully'}}
[2021-03-28 19:54:20] INFO Registration  Api Service  Started
[2021-03-28 19:54:20] INFO Update Content ended....
[2021-03-28 19:54:20] INFO {'status': True, 'data': {'message': 'data updated successfully'}}
[2021-03-28 19:54:24] INFO ListContent  Api Service  Started
[2021-03-28 19:54:24] INFO List Content ended....
[2021-03-28 19:54:24] INFO {'success': True, 'data': [OrderedDict([('content_id', 1), ('title', "('title_1',)"), ('body', "('body_1',)"), ('summary', "('summary_1',)"), ('pdf_document_path', 'files/1_20210328-195420.pdf'), ('categories', 'blog_writer')]), OrderedDict([('content_id', 2), ('title', 'title2'), ('body', 'body2'), ('summary', 'summary2'), ('pdf_document_path', 'files/2_20210328-194222.pdf'), ('categories', 'blog_writer')]), OrderedDict([('content_id', 3), ('title', 'title2'), ('body', 'body2'), ('summary', 'summary2'), ('pdf_document_path', 'files/3_20210328-195144.pdf'), ('categories', 'blog_writer')])]}
[2021-03-28 19:55:14] INFO Registration  Api Service  Started
[2021-03-28 19:55:14] INFO Update Content ended....
[2021-03-28 19:55:14] INFO {'status': True, 'data': {'message': 'data updated successfully'}}
[2021-03-28 19:55:18] INFO ListContent  Api Service  Started
[2021-03-28 19:55:18] INFO List Content ended....
[2021-03-28 19:55:18] INFO {'success': True, 'data': [OrderedDict([('content_id', 1), ('title', 'title_1'), ('body', 'body_1'), ('summary', 'summary_1'), ('pdf_document_path', 'files/1_20210328-195514.pdf'), ('categories', 'blog_writer')]), OrderedDict([('content_id', 2), ('title', 'title2'), ('body', 'body2'), ('summary', 'summary2'), ('pdf_document_path', 'files/2_20210328-194222.pdf'), ('categories', 'blog_writer')]), OrderedDict([('content_id', 3), ('title', 'title2'), ('body', 'body2'), ('summary', 'summary2'), ('pdf_document_path', 'files/3_20210328-195144.pdf'), ('categories', 'blog_writer')])]}
[2021-03-28 19:56:28] INFO Registration  Api Service  Started
[2021-03-28 19:56:28] INFO Delete Content ended....
[2021-03-28 19:56:28] INFO {'status': False, 'data': {'message': 'Invalid Request'}}
[2021-03-28 19:56:39] INFO Registration  Api Service  Started
[2021-03-28 19:56:39] INFO Delete Content ended....
[2021-03-28 19:56:39] INFO {'status': True, 'data': {'message': 'data deleted successfully'}}
[2021-03-28 19:57:10] INFO ListContent  Api Service  Started
[2021-03-28 19:57:10] INFO List Content ended....
[2021-03-28 19:57:10] INFO {'success': True, 'data': [OrderedDict([('content_id', 2), ('title', 'title2'), ('body', 'body2'), ('summary', 'summary2'), ('pdf_document_path', 'files/2_20210328-194222.pdf'), ('categories', 'blog_writer')]), OrderedDict([('content_id', 3), ('title', 'title2'), ('body', 'body2'), ('summary', 'summary2'), ('pdf_document_path', 'files/3_20210328-195144.pdf'), ('categories', 'blog_writer')])]}
[2021-03-28 19:57:19] INFO Registration  Api Service  Started
[2021-03-28 19:57:19] INFO Delete Content ended....
[2021-03-28 19:57:19] INFO {'status': True, 'data': {'message': 'data deleted successfully'}}
[2021-03-28 20:02:32] INFO Registration  Api Service  Started
[2021-03-28 20:02:32] ERROR multiple repeat at position 9
[2021-03-28 20:02:32] ERROR Exception raised in Registration as multiple repeat at position 9
Traceback (most recent call last):
  File "G:\Care24\cms_backend\cms\helpers.py", line 71, in register
    is_valid = RegistrationSerializer(data=request_data).is_valid()
  File "G:\Care24\cms_backend\venv\lib\site-packages\rest_framework\serializers.py", line 220, in is_valid
    self._validated_data = self.run_validation(self.initial_data)
  File "G:\Care24\cms_backend\venv\lib\site-packages\rest_framework\serializers.py", line 419, in run_validation
    value = self.to_internal_value(data)
  File "G:\Care24\cms_backend\venv\lib\site-packages\rest_framework\serializers.py", line 476, in to_internal_value
    validated_value = field.run_validation(primitive_value)
  File "G:\Care24\cms_backend\venv\lib\site-packages\rest_framework\fields.py", line 799, in run_validation
    return super().run_validation(data)
  File "G:\Care24\cms_backend\venv\lib\site-packages\rest_framework\fields.py", line 569, in run_validation
    self.run_validators(value)
  File "G:\Care24\cms_backend\venv\lib\site-packages\rest_framework\fields.py", line 593, in run_validators
    validator(value)
  File "G:\Care24\cms_backend\venv\lib\site-packages\django\core\validators.py", line 46, in __call__
    regex_matches = self.regex.search(str(value))
  File "G:\Care24\cms_backend\venv\lib\site-packages\django\utils\functional.py", line 240, in inner
    self._setup()
  File "G:\Care24\cms_backend\venv\lib\site-packages\django\utils\functional.py", line 376, in _setup
    self._wrapped = self._setupfunc()
  File "G:\Care24\cms_backend\venv\lib\site-packages\django\utils\regex_helper.py", line 345, in _compile
    return re.compile(regex, flags)
  File "c:\users\lenovo\appdata\local\programs\python\python38\lib\re.py", line 252, in compile
    return _compile(pattern, flags)
  File "c:\users\lenovo\appdata\local\programs\python\python38\lib\re.py", line 304, in _compile
    p = sre_compile.compile(pattern, flags)
  File "c:\users\lenovo\appdata\local\programs\python\python38\lib\sre_compile.py", line 764, in compile
    p = sre_parse.parse(p, flags)
  File "c:\users\lenovo\appdata\local\programs\python\python38\lib\sre_parse.py", line 948, in parse
    p = _parse_sub(source, state, flags & SRE_FLAG_VERBOSE, 0)
  File "c:\users\lenovo\appdata\local\programs\python\python38\lib\sre_parse.py", line 443, in _parse_sub
    itemsappend(_parse(source, state, verbose, nested + 1,
  File "c:\users\lenovo\appdata\local\programs\python\python38\lib\sre_parse.py", line 671, in _parse
    raise source.error("multiple repeat",
re.error: multiple repeat at position 9
[2021-03-28 20:04:32] INFO Registration  Api Service  Started
[2021-03-28 20:04:32] INFO Registration ended....
[2021-03-28 20:04:32] INFO {'status': False, 'data': {'message': 'Invalid Request'}}
[2021-03-28 20:05:01] INFO Registration  Api Service  Started
[2021-03-28 20:05:01] ERROR multiple repeat at position 9
[2021-03-28 20:05:01] ERROR Exception raised in Registration as multiple repeat at position 9
Traceback (most recent call last):
  File "G:\Care24\cms_backend\cms\helpers.py", line 71, in register
    is_valid = RegistrationSerializer(data=request_data).is_valid()
  File "G:\Care24\cms_backend\venv\lib\site-packages\rest_framework\serializers.py", line 220, in is_valid
    self._validated_data = self.run_validation(self.initial_data)
  File "G:\Care24\cms_backend\venv\lib\site-packages\rest_framework\serializers.py", line 419, in run_validation
    value = self.to_internal_value(data)
  File "G:\Care24\cms_backend\venv\lib\site-packages\rest_framework\serializers.py", line 476, in to_internal_value
    validated_value = field.run_validation(primitive_value)
  File "G:\Care24\cms_backend\venv\lib\site-packages\rest_framework\fields.py", line 799, in run_validation
    return super().run_validation(data)
  File "G:\Care24\cms_backend\venv\lib\site-packages\rest_framework\fields.py", line 569, in run_validation
    self.run_validators(value)
  File "G:\Care24\cms_backend\venv\lib\site-packages\rest_framework\fields.py", line 593, in run_validators
    validator(value)
  File "G:\Care24\cms_backend\venv\lib\site-packages\django\core\validators.py", line 46, in __call__
    regex_matches = self.regex.search(str(value))
  File "G:\Care24\cms_backend\venv\lib\site-packages\django\utils\functional.py", line 240, in inner
    self._setup()
  File "G:\Care24\cms_backend\venv\lib\site-packages\django\utils\functional.py", line 376, in _setup
    self._wrapped = self._setupfunc()
  File "G:\Care24\cms_backend\venv\lib\site-packages\django\utils\regex_helper.py", line 345, in _compile
    return re.compile(regex, flags)
  File "c:\users\lenovo\appdata\local\programs\python\python38\lib\re.py", line 252, in compile
    return _compile(pattern, flags)
  File "c:\users\lenovo\appdata\local\programs\python\python38\lib\re.py", line 304, in _compile
    p = sre_compile.compile(pattern, flags)
  File "c:\users\lenovo\appdata\local\programs\python\python38\lib\sre_compile.py", line 764, in compile
    p = sre_parse.parse(p, flags)
  File "c:\users\lenovo\appdata\local\programs\python\python38\lib\sre_parse.py", line 948, in parse
    p = _parse_sub(source, state, flags & SRE_FLAG_VERBOSE, 0)
  File "c:\users\lenovo\appdata\local\programs\python\python38\lib\sre_parse.py", line 443, in _parse_sub
    itemsappend(_parse(source, state, verbose, nested + 1,
  File "c:\users\lenovo\appdata\local\programs\python\python38\lib\sre_parse.py", line 671, in _parse
    raise source.error("multiple repeat",
re.error: multiple repeat at position 9
[2021-03-28 20:05:27] INFO Registration  Api Service  Started
[2021-03-28 20:05:27] ERROR multiple repeat at position 6
[2021-03-28 20:05:27] ERROR Exception raised in Registration as multiple repeat at position 6
Traceback (most recent call last):
  File "G:\Care24\cms_backend\cms\helpers.py", line 71, in register
    is_valid = RegistrationSerializer(data=request_data).is_valid()
  File "G:\Care24\cms_backend\venv\lib\site-packages\rest_framework\serializers.py", line 220, in is_valid
    self._validated_data = self.run_validation(self.initial_data)
  File "G:\Care24\cms_backend\venv\lib\site-packages\rest_framework\serializers.py", line 419, in run_validation
    value = self.to_internal_value(data)
  File "G:\Care24\cms_backend\venv\lib\site-packages\rest_framework\serializers.py", line 476, in to_internal_value
    validated_value = field.run_validation(primitive_value)
  File "G:\Care24\cms_backend\venv\lib\site-packages\rest_framework\fields.py", line 799, in run_validation
    return super().run_validation(data)
  File "G:\Care24\cms_backend\venv\lib\site-packages\rest_framework\fields.py", line 569, in run_validation
    self.run_validators(value)
  File "G:\Care24\cms_backend\venv\lib\site-packages\rest_framework\fields.py", line 593, in run_validators
    validator(value)
  File "G:\Care24\cms_backend\venv\lib\site-packages\django\core\validators.py", line 46, in __call__
    regex_matches = self.regex.search(str(value))
  File "G:\Care24\cms_backend\venv\lib\site-packages\django\utils\functional.py", line 240, in inner
    self._setup()
  File "G:\Care24\cms_backend\venv\lib\site-packages\django\utils\functional.py", line 376, in _setup
    self._wrapped = self._setupfunc()
  File "G:\Care24\cms_backend\venv\lib\site-packages\django\utils\regex_helper.py", line 345, in _compile
    return re.compile(regex, flags)
  File "c:\users\lenovo\appdata\local\programs\python\python38\lib\re.py", line 252, in compile
    return _compile(pattern, flags)
  File "c:\users\lenovo\appdata\local\programs\python\python38\lib\re.py", line 304, in _compile
    p = sre_compile.compile(pattern, flags)
  File "c:\users\lenovo\appdata\local\programs\python\python38\lib\sre_compile.py", line 764, in compile
    p = sre_parse.parse(p, flags)
  File "c:\users\lenovo\appdata\local\programs\python\python38\lib\sre_parse.py", line 948, in parse
    p = _parse_sub(source, state, flags & SRE_FLAG_VERBOSE, 0)
  File "c:\users\lenovo\appdata\local\programs\python\python38\lib\sre_parse.py", line 443, in _parse_sub
    itemsappend(_parse(source, state, verbose, nested + 1,
  File "c:\users\lenovo\appdata\local\programs\python\python38\lib\sre_parse.py", line 671, in _parse
    raise source.error("multiple repeat",
re.error: multiple repeat at position 6
[2021-03-28 20:40:05] INFO Registration  Api Service  Started
[2021-03-28 20:40:05] INFO Registration ended....
[2021-03-28 20:40:05] INFO {'status': False, 'data': {'message': 'Invalid Request'}}
[2021-03-28 20:42:45] INFO Registration  Api Service  Started
[2021-03-28 20:42:45] INFO Registration ended....
[2021-03-28 20:42:45] INFO {'status': False, 'data': {'message': 'Invalid Request'}}
[2021-03-28 20:42:55] INFO Registration  Api Service  Started
[2021-03-28 20:42:55] INFO Registration ended....
[2021-03-28 20:42:55] INFO {'status': False, 'data': {'message': 'Invalid Request'}}
[2021-03-28 20:43:11] INFO Registration  Api Service  Started
[2021-03-28 20:43:12] INFO Registration ended....
[2021-03-28 20:43:12] INFO {'status': True, 'data': {'message': 'User registered successfully.', 'status_code': 15}}
[2021-03-28 20:43:29] INFO Registration  Api Service  Started
[2021-03-28 20:43:29] INFO Registration ended....
[2021-03-28 20:43:29] INFO {'status': False, 'data': {'message': 'Invalid Request'}}
[2021-03-28 20:43:41] INFO Registration  Api Service  Started
[2021-03-28 20:43:41] INFO Registration ended....
[2021-03-28 20:43:41] INFO {'status': False, 'data': {'message': 'Invalid Request'}}
[2021-03-28 20:51:22] INFO Registration  Api Service  Started
[2021-03-28 20:51:22] INFO Registration ended....
[2021-03-28 20:51:22] INFO {'status': False, 'data': {'message': 'Invalid Request'}}
[2021-03-28 20:51:22] INFO Registration  Api Service  Started
[2021-03-28 20:51:23] INFO Registration ended....
[2021-03-28 20:51:23] INFO {'status': True, 'data': {'message': 'User registered successfully.', 'status_code': 15}}
[2021-03-28 20:53:35] INFO Registration  Api Service  Started
[2021-03-28 20:53:36] INFO Registration ended....
[2021-03-28 20:53:36] INFO {'status': True, 'data': {'message': 'User registered successfully.', 'status_code': 15}}
[2021-03-28 20:53:36] INFO Registration  Api Service  Started
[2021-03-28 20:53:36] INFO Registration ended....
[2021-03-28 20:53:36] INFO {'status': False, 'data': {'message': 'Invalid Request'}}
[2021-03-28 20:53:36] INFO Registration  Api Service  Started
[2021-03-28 20:53:36] INFO Registration ended....
[2021-03-28 20:53:36] INFO {'status': False, 'data': {'message': 'Invalid Request'}}
[2021-03-28 20:53:36] INFO Registration  Api Service  Started
[2021-03-28 20:53:36] INFO Registration ended....
[2021-03-28 20:53:36] INFO {'status': True, 'data': {'message': 'User registered successfully.', 'status_code': 15}}
[2021-03-28 20:54:09] INFO login  Api Service  Started
[2021-03-28 20:54:10] INFO Login ended....
[2021-03-28 20:54:10] INFO {'success': True, 'data': {'user_id': 1, 'role_type': 'user', 'email_id': 'test@gmail.com', 'full_name': 'test', 'token': 'a22e5a01a943cc342ad5c6a2ae4c19cc8bca34fb'}}
[2021-03-28 20:54:34] INFO Registration  Api Service  Started
[2021-03-28 20:54:35] INFO Registration ended....
[2021-03-28 20:54:35] INFO {'status': True, 'data': {'message': 'User registered successfully.', 'status_code': 15}}
[2021-03-28 20:54:35] INFO login  Api Service  Started
[2021-03-28 20:54:37] ERROR HTTPConnectionPool(host='testserver', port=80): Max retries exceeded with url: /api-token-auth/ (Caused by NewConnectionError('<urllib3.connection.HTTPConnection object at 0x000001DA86941670>: Failed to establish a new connection: [Errno 11001] getaddrinfo failed'))
[2021-03-28 20:54:37] ERROR Exception raised in Login as HTTPConnectionPool(host='testserver', port=80): Max retries exceeded with url: /api-token-auth/ (Caused by NewConnectionError('<urllib3.connection.HTTPConnection object at 0x000001DA86941670>: Failed to establish a new connection: [Errno 11001] getaddrinfo failed'))
Traceback (most recent call last):
  File "G:\Care24\cms_backend\venv\lib\site-packages\urllib3\connection.py", line 169, in _new_conn
    conn = connection.create_connection(
  File "G:\Care24\cms_backend\venv\lib\site-packages\urllib3\util\connection.py", line 73, in create_connection
    for res in socket.getaddrinfo(host, port, family, socket.SOCK_STREAM):
  File "c:\users\lenovo\appdata\local\programs\python\python38\lib\socket.py", line 918, in getaddrinfo
    for res in _socket.getaddrinfo(host, port, family, type, proto, flags):
socket.gaierror: [Errno 11001] getaddrinfo failed

During handling of the above exception, another exception occurred:

Traceback (most recent call last):
  File "G:\Care24\cms_backend\venv\lib\site-packages\urllib3\connectionpool.py", line 699, in urlopen
    httplib_response = self._make_request(
  File "G:\Care24\cms_backend\venv\lib\site-packages\urllib3\connectionpool.py", line 394, in _make_request
    conn.request(method, url, **httplib_request_kw)
  File "G:\Care24\cms_backend\venv\lib\site-packages\urllib3\connection.py", line 234, in request
    super(HTTPConnection, self).request(method, url, body=body, headers=headers)
  File "c:\users\lenovo\appdata\local\programs\python\python38\lib\http\client.py", line 1255, in request
    self._send_request(method, url, body, headers, encode_chunked)
  File "c:\users\lenovo\appdata\local\programs\python\python38\lib\http\client.py", line 1301, in _send_request
    self.endheaders(body, encode_chunked=encode_chunked)
  File "c:\users\lenovo\appdata\local\programs\python\python38\lib\http\client.py", line 1250, in endheaders
    self._send_output(message_body, encode_chunked=encode_chunked)
  File "c:\users\lenovo\appdata\local\programs\python\python38\lib\http\client.py", line 1010, in _send_output
    self.send(msg)
  File "c:\users\lenovo\appdata\local\programs\python\python38\lib\http\client.py", line 950, in send
    self.connect()
  File "G:\Care24\cms_backend\venv\lib\site-packages\urllib3\connection.py", line 200, in connect
    conn = self._new_conn()
  File "G:\Care24\cms_backend\venv\lib\site-packages\urllib3\connection.py", line 181, in _new_conn
    raise NewConnectionError(
urllib3.exceptions.NewConnectionError: <urllib3.connection.HTTPConnection object at 0x000001DA86941670>: Failed to establish a new connection: [Errno 11001] getaddrinfo failed

During handling of the above exception, another exception occurred:

Traceback (most recent call last):
  File "G:\Care24\cms_backend\venv\lib\site-packages\requests\adapters.py", line 439, in send
    resp = conn.urlopen(
  File "G:\Care24\cms_backend\venv\lib\site-packages\urllib3\connectionpool.py", line 755, in urlopen
    retries = retries.increment(
  File "G:\Care24\cms_backend\venv\lib\site-packages\urllib3\util\retry.py", line 574, in increment
    raise MaxRetryError(_pool, url, error or ResponseError(cause))
urllib3.exceptions.MaxRetryError: HTTPConnectionPool(host='testserver', port=80): Max retries exceeded with url: /api-token-auth/ (Caused by NewConnectionError('<urllib3.connection.HTTPConnection object at 0x000001DA86941670>: Failed to establish a new connection: [Errno 11001] getaddrinfo failed'))

During handling of the above exception, another exception occurred:

Traceback (most recent call last):
  File "G:\Care24\cms_backend\cms\helpers.py", line 26, in login
    auth_token = shared.generate_auth_token(self, password=request_data.get("password"),
  File "G:\Care24\cms_backend\cms\shared.py", line 39, in generate_auth_token
    response = requests.post(settings.SERVER_PROTOCOLS + host + "/api-token-auth/",
  File "G:\Care24\cms_backend\venv\lib\site-packages\requests\api.py", line 119, in post
    return request('post', url, data=data, json=json, **kwargs)
  File "G:\Care24\cms_backend\venv\lib\site-packages\requests\api.py", line 61, in request
    return session.request(method=method, url=url, **kwargs)
  File "G:\Care24\cms_backend\venv\lib\site-packages\requests\sessions.py", line 542, in request
    resp = self.send(prep, **send_kwargs)
  File "G:\Care24\cms_backend\venv\lib\site-packages\requests\sessions.py", line 655, in send
    r = adapter.send(request, **kwargs)
  File "G:\Care24\cms_backend\venv\lib\site-packages\requests\adapters.py", line 516, in send
    raise ConnectionError(e, request=request)
requests.exceptions.ConnectionError: HTTPConnectionPool(host='testserver', port=80): Max retries exceeded with url: /api-token-auth/ (Caused by NewConnectionError('<urllib3.connection.HTTPConnection object at 0x000001DA86941670>: Failed to establish a new connection: [Errno 11001] getaddrinfo failed'))
[2021-03-28 20:54:38] INFO Registration  Api Service  Started
[2021-03-28 20:54:38] INFO Registration ended....
[2021-03-28 20:54:38] INFO {'status': False, 'data': {'message': 'Invalid Request'}}
[2021-03-28 20:54:38] INFO Registration  Api Service  Started
[2021-03-28 20:54:38] INFO Registration ended....
[2021-03-28 20:54:38] INFO {'status': True, 'data': {'message': 'User registered successfully.', 'status_code': 15}}
[2021-03-28 20:54:54] INFO login  Api Service  Started
[2021-03-28 20:54:54] INFO Login ended....
[2021-03-28 20:54:54] INFO {'status': False, 'data': {'message': 'Invalid Request'}}
[2021-03-28 20:55:55] INFO Registration  Api Service  Started
[2021-03-28 20:55:56] INFO Registration ended....
[2021-03-28 20:55:56] INFO {'status': True, 'data': {'message': 'User registered successfully.', 'status_code': 15}}
[2021-03-28 20:55:56] INFO login  Api Service  Started
[2021-03-28 20:55:58] ERROR HTTPConnectionPool(host='testserver', port=80): Max retries exceeded with url: /api-token-auth/ (Caused by NewConnectionError('<urllib3.connection.HTTPConnection object at 0x000001A9605C57C0>: Failed to establish a new connection: [Errno 11001] getaddrinfo failed'))
[2021-03-28 20:55:58] ERROR Exception raised in Login as HTTPConnectionPool(host='testserver', port=80): Max retries exceeded with url: /api-token-auth/ (Caused by NewConnectionError('<urllib3.connection.HTTPConnection object at 0x000001A9605C57C0>: Failed to establish a new connection: [Errno 11001] getaddrinfo failed'))
Traceback (most recent call last):
  File "G:\Care24\cms_backend\venv\lib\site-packages\urllib3\connection.py", line 169, in _new_conn
    conn = connection.create_connection(
  File "G:\Care24\cms_backend\venv\lib\site-packages\urllib3\util\connection.py", line 73, in create_connection
    for res in socket.getaddrinfo(host, port, family, socket.SOCK_STREAM):
  File "c:\users\lenovo\appdata\local\programs\python\python38\lib\socket.py", line 918, in getaddrinfo
    for res in _socket.getaddrinfo(host, port, family, type, proto, flags):
socket.gaierror: [Errno 11001] getaddrinfo failed

During handling of the above exception, another exception occurred:

Traceback (most recent call last):
  File "G:\Care24\cms_backend\venv\lib\site-packages\urllib3\connectionpool.py", line 699, in urlopen
    httplib_response = self._make_request(
  File "G:\Care24\cms_backend\venv\lib\site-packages\urllib3\connectionpool.py", line 394, in _make_request
    conn.request(method, url, **httplib_request_kw)
  File "G:\Care24\cms_backend\venv\lib\site-packages\urllib3\connection.py", line 234, in request
    super(HTTPConnection, self).request(method, url, body=body, headers=headers)
  File "c:\users\lenovo\appdata\local\programs\python\python38\lib\http\client.py", line 1255, in request
    self._send_request(method, url, body, headers, encode_chunked)
  File "c:\users\lenovo\appdata\local\programs\python\python38\lib\http\client.py", line 1301, in _send_request
    self.endheaders(body, encode_chunked=encode_chunked)
  File "c:\users\lenovo\appdata\local\programs\python\python38\lib\http\client.py", line 1250, in endheaders
    self._send_output(message_body, encode_chunked=encode_chunked)
  File "c:\users\lenovo\appdata\local\programs\python\python38\lib\http\client.py", line 1010, in _send_output
    self.send(msg)
  File "c:\users\lenovo\appdata\local\programs\python\python38\lib\http\client.py", line 950, in send
    self.connect()
  File "G:\Care24\cms_backend\venv\lib\site-packages\urllib3\connection.py", line 200, in connect
    conn = self._new_conn()
  File "G:\Care24\cms_backend\venv\lib\site-packages\urllib3\connection.py", line 181, in _new_conn
    raise NewConnectionError(
urllib3.exceptions.NewConnectionError: <urllib3.connection.HTTPConnection object at 0x000001A9605C57C0>: Failed to establish a new connection: [Errno 11001] getaddrinfo failed

During handling of the above exception, another exception occurred:

Traceback (most recent call last):
  File "G:\Care24\cms_backend\venv\lib\site-packages\requests\adapters.py", line 439, in send
    resp = conn.urlopen(
  File "G:\Care24\cms_backend\venv\lib\site-packages\urllib3\connectionpool.py", line 755, in urlopen
    retries = retries.increment(
  File "G:\Care24\cms_backend\venv\lib\site-packages\urllib3\util\retry.py", line 574, in increment
    raise MaxRetryError(_pool, url, error or ResponseError(cause))
urllib3.exceptions.MaxRetryError: HTTPConnectionPool(host='testserver', port=80): Max retries exceeded with url: /api-token-auth/ (Caused by NewConnectionError('<urllib3.connection.HTTPConnection object at 0x000001A9605C57C0>: Failed to establish a new connection: [Errno 11001] getaddrinfo failed'))

During handling of the above exception, another exception occurred:

Traceback (most recent call last):
  File "G:\Care24\cms_backend\cms\helpers.py", line 26, in login
    auth_token = shared.generate_auth_token(self, password=request_data.get("password"),
  File "G:\Care24\cms_backend\cms\shared.py", line 39, in generate_auth_token
    response = requests.post(settings.SERVER_PROTOCOLS + host + "/api-token-auth/",
  File "G:\Care24\cms_backend\venv\lib\site-packages\requests\api.py", line 119, in post
    return request('post', url, data=data, json=json, **kwargs)
  File "G:\Care24\cms_backend\venv\lib\site-packages\requests\api.py", line 61, in request
    return session.request(method=method, url=url, **kwargs)
  File "G:\Care24\cms_backend\venv\lib\site-packages\requests\sessions.py", line 542, in request
    resp = self.send(prep, **send_kwargs)
  File "G:\Care24\cms_backend\venv\lib\site-packages\requests\sessions.py", line 655, in send
    r = adapter.send(request, **kwargs)
  File "G:\Care24\cms_backend\venv\lib\site-packages\requests\adapters.py", line 516, in send
    raise ConnectionError(e, request=request)
requests.exceptions.ConnectionError: HTTPConnectionPool(host='testserver', port=80): Max retries exceeded with url: /api-token-auth/ (Caused by NewConnectionError('<urllib3.connection.HTTPConnection object at 0x000001A9605C57C0>: Failed to establish a new connection: [Errno 11001] getaddrinfo failed'))
[2021-03-28 20:55:58] INFO Registration  Api Service  Started
[2021-03-28 20:55:58] INFO Registration ended....
[2021-03-28 20:55:58] INFO {'status': False, 'data': {'message': 'Invalid Request'}}
[2021-03-28 20:55:58] INFO Registration  Api Service  Started
[2021-03-28 20:55:59] INFO Registration ended....
[2021-03-28 20:55:59] INFO {'status': True, 'data': {'message': 'User registered successfully.', 'status_code': 15}}
[2021-03-28 20:56:13] INFO Registration  Api Service  Started
[2021-03-28 20:56:13] INFO Registration ended....
[2021-03-28 20:56:13] INFO {'status': True, 'data': {'message': 'User registered successfully.', 'status_code': 15}}
[2021-03-28 20:56:13] INFO login  Api Service  Started
[2021-03-28 20:56:16] ERROR HTTPConnectionPool(host='testserver', port=80): Max retries exceeded with url: /api-token-auth/ (Caused by NewConnectionError('<urllib3.connection.HTTPConnection object at 0x000001D90EB60940>: Failed to establish a new connection: [Errno 11001] getaddrinfo failed'))
[2021-03-28 20:56:16] ERROR Exception raised in Login as HTTPConnectionPool(host='testserver', port=80): Max retries exceeded with url: /api-token-auth/ (Caused by NewConnectionError('<urllib3.connection.HTTPConnection object at 0x000001D90EB60940>: Failed to establish a new connection: [Errno 11001] getaddrinfo failed'))
Traceback (most recent call last):
  File "G:\Care24\cms_backend\venv\lib\site-packages\urllib3\connection.py", line 169, in _new_conn
    conn = connection.create_connection(
  File "G:\Care24\cms_backend\venv\lib\site-packages\urllib3\util\connection.py", line 73, in create_connection
    for res in socket.getaddrinfo(host, port, family, socket.SOCK_STREAM):
  File "c:\users\lenovo\appdata\local\programs\python\python38\lib\socket.py", line 918, in getaddrinfo
    for res in _socket.getaddrinfo(host, port, family, type, proto, flags):
socket.gaierror: [Errno 11001] getaddrinfo failed

During handling of the above exception, another exception occurred:

Traceback (most recent call last):
  File "G:\Care24\cms_backend\venv\lib\site-packages\urllib3\connectionpool.py", line 699, in urlopen
    httplib_response = self._make_request(
  File "G:\Care24\cms_backend\venv\lib\site-packages\urllib3\connectionpool.py", line 394, in _make_request
    conn.request(method, url, **httplib_request_kw)
  File "G:\Care24\cms_backend\venv\lib\site-packages\urllib3\connection.py", line 234, in request
    super(HTTPConnection, self).request(method, url, body=body, headers=headers)
  File "c:\users\lenovo\appdata\local\programs\python\python38\lib\http\client.py", line 1255, in request
    self._send_request(method, url, body, headers, encode_chunked)
  File "c:\users\lenovo\appdata\local\programs\python\python38\lib\http\client.py", line 1301, in _send_request
    self.endheaders(body, encode_chunked=encode_chunked)
  File "c:\users\lenovo\appdata\local\programs\python\python38\lib\http\client.py", line 1250, in endheaders
    self._send_output(message_body, encode_chunked=encode_chunked)
  File "c:\users\lenovo\appdata\local\programs\python\python38\lib\http\client.py", line 1010, in _send_output
    self.send(msg)
  File "c:\users\lenovo\appdata\local\programs\python\python38\lib\http\client.py", line 950, in send
    self.connect()
  File "G:\Care24\cms_backend\venv\lib\site-packages\urllib3\connection.py", line 200, in connect
    conn = self._new_conn()
  File "G:\Care24\cms_backend\venv\lib\site-packages\urllib3\connection.py", line 181, in _new_conn
    raise NewConnectionError(
urllib3.exceptions.NewConnectionError: <urllib3.connection.HTTPConnection object at 0x000001D90EB60940>: Failed to establish a new connection: [Errno 11001] getaddrinfo failed

During handling of the above exception, another exception occurred:

Traceback (most recent call last):
  File "G:\Care24\cms_backend\venv\lib\site-packages\requests\adapters.py", line 439, in send
    resp = conn.urlopen(
  File "G:\Care24\cms_backend\venv\lib\site-packages\urllib3\connectionpool.py", line 755, in urlopen
    retries = retries.increment(
  File "G:\Care24\cms_backend\venv\lib\site-packages\urllib3\util\retry.py", line 574, in increment
    raise MaxRetryError(_pool, url, error or ResponseError(cause))
urllib3.exceptions.MaxRetryError: HTTPConnectionPool(host='testserver', port=80): Max retries exceeded with url: /api-token-auth/ (Caused by NewConnectionError('<urllib3.connection.HTTPConnection object at 0x000001D90EB60940>: Failed to establish a new connection: [Errno 11001] getaddrinfo failed'))

During handling of the above exception, another exception occurred:

Traceback (most recent call last):
  File "G:\Care24\cms_backend\cms\helpers.py", line 26, in login
    auth_token = shared.generate_auth_token(self, password=request_data.get("password"),
  File "G:\Care24\cms_backend\cms\shared.py", line 39, in generate_auth_token
    response = requests.post(settings.SERVER_PROTOCOLS + host + "/api-token-auth/",
  File "G:\Care24\cms_backend\venv\lib\site-packages\requests\api.py", line 119, in post
    return request('post', url, data=data, json=json, **kwargs)
  File "G:\Care24\cms_backend\venv\lib\site-packages\requests\api.py", line 61, in request
    return session.request(method=method, url=url, **kwargs)
  File "G:\Care24\cms_backend\venv\lib\site-packages\requests\sessions.py", line 542, in request
    resp = self.send(prep, **send_kwargs)
  File "G:\Care24\cms_backend\venv\lib\site-packages\requests\sessions.py", line 655, in send
    r = adapter.send(request, **kwargs)
  File "G:\Care24\cms_backend\venv\lib\site-packages\requests\adapters.py", line 516, in send
    raise ConnectionError(e, request=request)
requests.exceptions.ConnectionError: HTTPConnectionPool(host='testserver', port=80): Max retries exceeded with url: /api-token-auth/ (Caused by NewConnectionError('<urllib3.connection.HTTPConnection object at 0x000001D90EB60940>: Failed to establish a new connection: [Errno 11001] getaddrinfo failed'))
[2021-03-28 20:56:16] INFO Registration  Api Service  Started
[2021-03-28 20:56:16] INFO Registration ended....
[2021-03-28 20:56:16] INFO {'status': False, 'data': {'message': 'Invalid Request'}}
[2021-03-28 20:56:16] INFO Registration  Api Service  Started
[2021-03-28 20:56:16] INFO Registration ended....
[2021-03-28 20:56:16] INFO {'status': True, 'data': {'message': 'User registered successfully.', 'status_code': 15}}
[2021-03-28 20:56:43] INFO Registration  Api Service  Started
[2021-03-28 20:56:43] INFO Registration ended....
[2021-03-28 20:56:43] INFO {'status': True, 'data': {'message': 'User registered successfully.', 'status_code': 15}}
[2021-03-28 20:56:43] INFO login  Api Service  Started
[2021-03-28 20:56:46] ERROR HTTPConnectionPool(host='testserver', port=80): Max retries exceeded with url: /api-token-auth/ (Caused by NewConnectionError('<urllib3.connection.HTTPConnection object at 0x000002078E03F580>: Failed to establish a new connection: [Errno 11001] getaddrinfo failed'))
[2021-03-28 20:56:46] ERROR Exception raised in Login as HTTPConnectionPool(host='testserver', port=80): Max retries exceeded with url: /api-token-auth/ (Caused by NewConnectionError('<urllib3.connection.HTTPConnection object at 0x000002078E03F580>: Failed to establish a new connection: [Errno 11001] getaddrinfo failed'))
Traceback (most recent call last):
  File "G:\Care24\cms_backend\venv\lib\site-packages\urllib3\connection.py", line 169, in _new_conn
    conn = connection.create_connection(
  File "G:\Care24\cms_backend\venv\lib\site-packages\urllib3\util\connection.py", line 73, in create_connection
    for res in socket.getaddrinfo(host, port, family, socket.SOCK_STREAM):
  File "c:\users\lenovo\appdata\local\programs\python\python38\lib\socket.py", line 918, in getaddrinfo
    for res in _socket.getaddrinfo(host, port, family, type, proto, flags):
socket.gaierror: [Errno 11001] getaddrinfo failed

During handling of the above exception, another exception occurred:

Traceback (most recent call last):
  File "G:\Care24\cms_backend\venv\lib\site-packages\urllib3\connectionpool.py", line 699, in urlopen
    httplib_response = self._make_request(
  File "G:\Care24\cms_backend\venv\lib\site-packages\urllib3\connectionpool.py", line 394, in _make_request
    conn.request(method, url, **httplib_request_kw)
  File "G:\Care24\cms_backend\venv\lib\site-packages\urllib3\connection.py", line 234, in request
    super(HTTPConnection, self).request(method, url, body=body, headers=headers)
  File "c:\users\lenovo\appdata\local\programs\python\python38\lib\http\client.py", line 1255, in request
    self._send_request(method, url, body, headers, encode_chunked)
  File "c:\users\lenovo\appdata\local\programs\python\python38\lib\http\client.py", line 1301, in _send_request
    self.endheaders(body, encode_chunked=encode_chunked)
  File "c:\users\lenovo\appdata\local\programs\python\python38\lib\http\client.py", line 1250, in endheaders
    self._send_output(message_body, encode_chunked=encode_chunked)
  File "c:\users\lenovo\appdata\local\programs\python\python38\lib\http\client.py", line 1010, in _send_output
    self.send(msg)
  File "c:\users\lenovo\appdata\local\programs\python\python38\lib\http\client.py", line 950, in send
    self.connect()
  File "G:\Care24\cms_backend\venv\lib\site-packages\urllib3\connection.py", line 200, in connect
    conn = self._new_conn()
  File "G:\Care24\cms_backend\venv\lib\site-packages\urllib3\connection.py", line 181, in _new_conn
    raise NewConnectionError(
urllib3.exceptions.NewConnectionError: <urllib3.connection.HTTPConnection object at 0x000002078E03F580>: Failed to establish a new connection: [Errno 11001] getaddrinfo failed

During handling of the above exception, another exception occurred:

Traceback (most recent call last):
  File "G:\Care24\cms_backend\venv\lib\site-packages\requests\adapters.py", line 439, in send
    resp = conn.urlopen(
  File "G:\Care24\cms_backend\venv\lib\site-packages\urllib3\connectionpool.py", line 755, in urlopen
    retries = retries.increment(
  File "G:\Care24\cms_backend\venv\lib\site-packages\urllib3\util\retry.py", line 574, in increment
    raise MaxRetryError(_pool, url, error or ResponseError(cause))
urllib3.exceptions.MaxRetryError: HTTPConnectionPool(host='testserver', port=80): Max retries exceeded with url: /api-token-auth/ (Caused by NewConnectionError('<urllib3.connection.HTTPConnection object at 0x000002078E03F580>: Failed to establish a new connection: [Errno 11001] getaddrinfo failed'))

During handling of the above exception, another exception occurred:

Traceback (most recent call last):
  File "G:\Care24\cms_backend\cms\helpers.py", line 26, in login
    auth_token = shared.generate_auth_token(self, password=request_data.get("password"),
  File "G:\Care24\cms_backend\cms\shared.py", line 39, in generate_auth_token
    response = requests.post(settings.SERVER_PROTOCOLS + host + "/api-token-auth/",
  File "G:\Care24\cms_backend\venv\lib\site-packages\requests\api.py", line 119, in post
    return request('post', url, data=data, json=json, **kwargs)
  File "G:\Care24\cms_backend\venv\lib\site-packages\requests\api.py", line 61, in request
    return session.request(method=method, url=url, **kwargs)
  File "G:\Care24\cms_backend\venv\lib\site-packages\requests\sessions.py", line 542, in request
    resp = self.send(prep, **send_kwargs)
  File "G:\Care24\cms_backend\venv\lib\site-packages\requests\sessions.py", line 655, in send
    r = adapter.send(request, **kwargs)
  File "G:\Care24\cms_backend\venv\lib\site-packages\requests\adapters.py", line 516, in send
    raise ConnectionError(e, request=request)
requests.exceptions.ConnectionError: HTTPConnectionPool(host='testserver', port=80): Max retries exceeded with url: /api-token-auth/ (Caused by NewConnectionError('<urllib3.connection.HTTPConnection object at 0x000002078E03F580>: Failed to establish a new connection: [Errno 11001] getaddrinfo failed'))
[2021-03-28 20:56:46] INFO Registration  Api Service  Started
[2021-03-28 20:56:46] INFO Registration ended....
[2021-03-28 20:56:46] INFO {'status': False, 'data': {'message': 'Invalid Request'}}
[2021-03-28 20:56:46] INFO Registration  Api Service  Started
[2021-03-28 20:56:46] INFO Registration ended....
[2021-03-28 20:56:46] INFO {'status': True, 'data': {'message': 'User registered successfully.', 'status_code': 15}}
[2021-03-28 20:57:30] INFO Registration  Api Service  Started
[2021-03-28 20:57:30] INFO Registration ended....
[2021-03-28 20:57:30] INFO {'status': True, 'data': {'message': 'User registered successfully.', 'status_code': 15}}
[2021-03-28 20:57:30] INFO login  Api Service  Started
[2021-03-28 20:57:33] ERROR HTTPConnectionPool(host='testserver', port=80): Max retries exceeded with url: /api-token-auth/ (Caused by NewConnectionError('<urllib3.connection.HTTPConnection object at 0x0000026CEA8B20A0>: Failed to establish a new connection: [Errno 11001] getaddrinfo failed'))
[2021-03-28 20:57:33] ERROR Exception raised in Login as HTTPConnectionPool(host='testserver', port=80): Max retries exceeded with url: /api-token-auth/ (Caused by NewConnectionError('<urllib3.connection.HTTPConnection object at 0x0000026CEA8B20A0>: Failed to establish a new connection: [Errno 11001] getaddrinfo failed'))
Traceback (most recent call last):
  File "G:\Care24\cms_backend\venv\lib\site-packages\urllib3\connection.py", line 169, in _new_conn
    conn = connection.create_connection(
  File "G:\Care24\cms_backend\venv\lib\site-packages\urllib3\util\connection.py", line 73, in create_connection
    for res in socket.getaddrinfo(host, port, family, socket.SOCK_STREAM):
  File "c:\users\lenovo\appdata\local\programs\python\python38\lib\socket.py", line 918, in getaddrinfo
    for res in _socket.getaddrinfo(host, port, family, type, proto, flags):
socket.gaierror: [Errno 11001] getaddrinfo failed

During handling of the above exception, another exception occurred:

Traceback (most recent call last):
  File "G:\Care24\cms_backend\venv\lib\site-packages\urllib3\connectionpool.py", line 699, in urlopen
    httplib_response = self._make_request(
  File "G:\Care24\cms_backend\venv\lib\site-packages\urllib3\connectionpool.py", line 394, in _make_request
    conn.request(method, url, **httplib_request_kw)
  File "G:\Care24\cms_backend\venv\lib\site-packages\urllib3\connection.py", line 234, in request
    super(HTTPConnection, self).request(method, url, body=body, headers=headers)
  File "c:\users\lenovo\appdata\local\programs\python\python38\lib\http\client.py", line 1255, in request
    self._send_request(method, url, body, headers, encode_chunked)
  File "c:\users\lenovo\appdata\local\programs\python\python38\lib\http\client.py", line 1301, in _send_request
    self.endheaders(body, encode_chunked=encode_chunked)
  File "c:\users\lenovo\appdata\local\programs\python\python38\lib\http\client.py", line 1250, in endheaders
    self._send_output(message_body, encode_chunked=encode_chunked)
  File "c:\users\lenovo\appdata\local\programs\python\python38\lib\http\client.py", line 1010, in _send_output
    self.send(msg)
  File "c:\users\lenovo\appdata\local\programs\python\python38\lib\http\client.py", line 950, in send
    self.connect()
  File "G:\Care24\cms_backend\venv\lib\site-packages\urllib3\connection.py", line 200, in connect
    conn = self._new_conn()
  File "G:\Care24\cms_backend\venv\lib\site-packages\urllib3\connection.py", line 181, in _new_conn
    raise NewConnectionError(
urllib3.exceptions.NewConnectionError: <urllib3.connection.HTTPConnection object at 0x0000026CEA8B20A0>: Failed to establish a new connection: [Errno 11001] getaddrinfo failed

During handling of the above exception, another exception occurred:

Traceback (most recent call last):
  File "G:\Care24\cms_backend\venv\lib\site-packages\requests\adapters.py", line 439, in send
    resp = conn.urlopen(
  File "G:\Care24\cms_backend\venv\lib\site-packages\urllib3\connectionpool.py", line 755, in urlopen
    retries = retries.increment(
  File "G:\Care24\cms_backend\venv\lib\site-packages\urllib3\util\retry.py", line 574, in increment
    raise MaxRetryError(_pool, url, error or ResponseError(cause))
urllib3.exceptions.MaxRetryError: HTTPConnectionPool(host='testserver', port=80): Max retries exceeded with url: /api-token-auth/ (Caused by NewConnectionError('<urllib3.connection.HTTPConnection object at 0x0000026CEA8B20A0>: Failed to establish a new connection: [Errno 11001] getaddrinfo failed'))

During handling of the above exception, another exception occurred:

Traceback (most recent call last):
  File "G:\Care24\cms_backend\cms\helpers.py", line 26, in login
    auth_token = shared.generate_auth_token(self, password=request_data.get("password"),
  File "G:\Care24\cms_backend\cms\shared.py", line 39, in generate_auth_token
    response = requests.post(settings.SERVER_PROTOCOLS + host + "/api-token-auth/",
  File "G:\Care24\cms_backend\venv\lib\site-packages\requests\api.py", line 119, in post
    return request('post', url, data=data, json=json, **kwargs)
  File "G:\Care24\cms_backend\venv\lib\site-packages\requests\api.py", line 61, in request
    return session.request(method=method, url=url, **kwargs)
  File "G:\Care24\cms_backend\venv\lib\site-packages\requests\sessions.py", line 542, in request
    resp = self.send(prep, **send_kwargs)
  File "G:\Care24\cms_backend\venv\lib\site-packages\requests\sessions.py", line 655, in send
    r = adapter.send(request, **kwargs)
  File "G:\Care24\cms_backend\venv\lib\site-packages\requests\adapters.py", line 516, in send
    raise ConnectionError(e, request=request)
requests.exceptions.ConnectionError: HTTPConnectionPool(host='testserver', port=80): Max retries exceeded with url: /api-token-auth/ (Caused by NewConnectionError('<urllib3.connection.HTTPConnection object at 0x0000026CEA8B20A0>: Failed to establish a new connection: [Errno 11001] getaddrinfo failed'))
[2021-03-28 20:57:33] INFO Registration  Api Service  Started
[2021-03-28 20:57:33] INFO Registration ended....
[2021-03-28 20:57:33] INFO {'status': False, 'data': {'message': 'Invalid Request'}}
[2021-03-28 20:57:33] INFO Registration  Api Service  Started
[2021-03-28 20:57:33] INFO Registration ended....
[2021-03-28 20:57:33] INFO {'status': True, 'data': {'message': 'User registered successfully.', 'status_code': 15}}
[2021-03-28 21:03:02] INFO Registration  Api Service  Started
[2021-03-28 21:03:03] INFO Registration ended....
[2021-03-28 21:03:03] INFO {'status': True, 'data': {'message': 'User registered successfully.', 'status_code': 15}}
[2021-03-28 21:03:03] INFO login  Api Service  Started
[2021-03-28 21:03:05] ERROR HTTPConnectionPool(host='testserver', port=80): Max retries exceeded with url: /api-token-auth/ (Caused by NewConnectionError('<urllib3.connection.HTTPConnection object at 0x000002B22F77F790>: Failed to establish a new connection: [Errno 11001] getaddrinfo failed'))
[2021-03-28 21:03:05] ERROR Exception raised in Login as HTTPConnectionPool(host='testserver', port=80): Max retries exceeded with url: /api-token-auth/ (Caused by NewConnectionError('<urllib3.connection.HTTPConnection object at 0x000002B22F77F790>: Failed to establish a new connection: [Errno 11001] getaddrinfo failed'))
Traceback (most recent call last):
  File "G:\Care24\cms_backend\venv\lib\site-packages\urllib3\connection.py", line 169, in _new_conn
    conn = connection.create_connection(
  File "G:\Care24\cms_backend\venv\lib\site-packages\urllib3\util\connection.py", line 73, in create_connection
    for res in socket.getaddrinfo(host, port, family, socket.SOCK_STREAM):
  File "c:\users\lenovo\appdata\local\programs\python\python38\lib\socket.py", line 918, in getaddrinfo
    for res in _socket.getaddrinfo(host, port, family, type, proto, flags):
socket.gaierror: [Errno 11001] getaddrinfo failed

During handling of the above exception, another exception occurred:

Traceback (most recent call last):
  File "G:\Care24\cms_backend\venv\lib\site-packages\urllib3\connectionpool.py", line 699, in urlopen
    httplib_response = self._make_request(
  File "G:\Care24\cms_backend\venv\lib\site-packages\urllib3\connectionpool.py", line 394, in _make_request
    conn.request(method, url, **httplib_request_kw)
  File "G:\Care24\cms_backend\venv\lib\site-packages\urllib3\connection.py", line 234, in request
    super(HTTPConnection, self).request(method, url, body=body, headers=headers)
  File "c:\users\lenovo\appdata\local\programs\python\python38\lib\http\client.py", line 1255, in request
    self._send_request(method, url, body, headers, encode_chunked)
  File "c:\users\lenovo\appdata\local\programs\python\python38\lib\http\client.py", line 1301, in _send_request
    self.endheaders(body, encode_chunked=encode_chunked)
  File "c:\users\lenovo\appdata\local\programs\python\python38\lib\http\client.py", line 1250, in endheaders
    self._send_output(message_body, encode_chunked=encode_chunked)
  File "c:\users\lenovo\appdata\local\programs\python\python38\lib\http\client.py", line 1010, in _send_output
    self.send(msg)
  File "c:\users\lenovo\appdata\local\programs\python\python38\lib\http\client.py", line 950, in send
    self.connect()
  File "G:\Care24\cms_backend\venv\lib\site-packages\urllib3\connection.py", line 200, in connect
    conn = self._new_conn()
  File "G:\Care24\cms_backend\venv\lib\site-packages\urllib3\connection.py", line 181, in _new_conn
    raise NewConnectionError(
urllib3.exceptions.NewConnectionError: <urllib3.connection.HTTPConnection object at 0x000002B22F77F790>: Failed to establish a new connection: [Errno 11001] getaddrinfo failed

During handling of the above exception, another exception occurred:

Traceback (most recent call last):
  File "G:\Care24\cms_backend\venv\lib\site-packages\requests\adapters.py", line 439, in send
    resp = conn.urlopen(
  File "G:\Care24\cms_backend\venv\lib\site-packages\urllib3\connectionpool.py", line 755, in urlopen
    retries = retries.increment(
  File "G:\Care24\cms_backend\venv\lib\site-packages\urllib3\util\retry.py", line 574, in increment
    raise MaxRetryError(_pool, url, error or ResponseError(cause))
urllib3.exceptions.MaxRetryError: HTTPConnectionPool(host='testserver', port=80): Max retries exceeded with url: /api-token-auth/ (Caused by NewConnectionError('<urllib3.connection.HTTPConnection object at 0x000002B22F77F790>: Failed to establish a new connection: [Errno 11001] getaddrinfo failed'))

During handling of the above exception, another exception occurred:

Traceback (most recent call last):
  File "G:\Care24\cms_backend\cms\helpers.py", line 26, in login
    auth_token = shared.generate_auth_token(self, password=request_data.get("password"),
  File "G:\Care24\cms_backend\cms\shared.py", line 39, in generate_auth_token
    response = requests.post(settings.SERVER_PROTOCOLS + host + "/api-token-auth/",
  File "G:\Care24\cms_backend\venv\lib\site-packages\requests\api.py", line 119, in post
    return request('post', url, data=data, json=json, **kwargs)
  File "G:\Care24\cms_backend\venv\lib\site-packages\requests\api.py", line 61, in request
    return session.request(method=method, url=url, **kwargs)
  File "G:\Care24\cms_backend\venv\lib\site-packages\requests\sessions.py", line 542, in request
    resp = self.send(prep, **send_kwargs)
  File "G:\Care24\cms_backend\venv\lib\site-packages\requests\sessions.py", line 655, in send
    r = adapter.send(request, **kwargs)
  File "G:\Care24\cms_backend\venv\lib\site-packages\requests\adapters.py", line 516, in send
    raise ConnectionError(e, request=request)
requests.exceptions.ConnectionError: HTTPConnectionPool(host='testserver', port=80): Max retries exceeded with url: /api-token-auth/ (Caused by NewConnectionError('<urllib3.connection.HTTPConnection object at 0x000002B22F77F790>: Failed to establish a new connection: [Errno 11001] getaddrinfo failed'))
[2021-03-28 21:03:06] INFO Registration  Api Service  Started
[2021-03-28 21:03:06] INFO Registration ended....
[2021-03-28 21:03:06] INFO {'status': False, 'data': {'message': 'Invalid Request'}}
[2021-03-28 21:03:06] INFO Registration  Api Service  Started
[2021-03-28 21:03:06] INFO Registration ended....
[2021-03-28 21:03:06] INFO {'status': True, 'data': {'message': 'User registered successfully.', 'status_code': 15}}
[2021-03-28 21:04:36] INFO Registration  Api Service  Started
[2021-03-28 21:04:37] INFO Registration ended....
[2021-03-28 21:04:37] INFO {'status': True, 'data': {'message': 'User registered successfully.', 'status_code': 15}}
[2021-03-28 21:04:37] INFO login  Api Service  Started
[2021-03-28 21:04:39] ERROR HTTPConnectionPool(host='testserver', port=80): Max retries exceeded with url: /api-token-auth/ (Caused by NewConnectionError('<urllib3.connection.HTTPConnection object at 0x00000260DA5D8A00>: Failed to establish a new connection: [Errno 11001] getaddrinfo failed'))
[2021-03-28 21:04:39] ERROR Exception raised in Login as HTTPConnectionPool(host='testserver', port=80): Max retries exceeded with url: /api-token-auth/ (Caused by NewConnectionError('<urllib3.connection.HTTPConnection object at 0x00000260DA5D8A00>: Failed to establish a new connection: [Errno 11001] getaddrinfo failed'))
Traceback (most recent call last):
  File "G:\Care24\cms_backend\venv\lib\site-packages\urllib3\connection.py", line 169, in _new_conn
    conn = connection.create_connection(
  File "G:\Care24\cms_backend\venv\lib\site-packages\urllib3\util\connection.py", line 73, in create_connection
    for res in socket.getaddrinfo(host, port, family, socket.SOCK_STREAM):
  File "c:\users\lenovo\appdata\local\programs\python\python38\lib\socket.py", line 918, in getaddrinfo
    for res in _socket.getaddrinfo(host, port, family, type, proto, flags):
socket.gaierror: [Errno 11001] getaddrinfo failed

During handling of the above exception, another exception occurred:

Traceback (most recent call last):
  File "G:\Care24\cms_backend\venv\lib\site-packages\urllib3\connectionpool.py", line 699, in urlopen
    httplib_response = self._make_request(
  File "G:\Care24\cms_backend\venv\lib\site-packages\urllib3\connectionpool.py", line 394, in _make_request
    conn.request(method, url, **httplib_request_kw)
  File "G:\Care24\cms_backend\venv\lib\site-packages\urllib3\connection.py", line 234, in request
    super(HTTPConnection, self).request(method, url, body=body, headers=headers)
  File "c:\users\lenovo\appdata\local\programs\python\python38\lib\http\client.py", line 1255, in request
    self._send_request(method, url, body, headers, encode_chunked)
  File "c:\users\lenovo\appdata\local\programs\python\python38\lib\http\client.py", line 1301, in _send_request
    self.endheaders(body, encode_chunked=encode_chunked)
  File "c:\users\lenovo\appdata\local\programs\python\python38\lib\http\client.py", line 1250, in endheaders
    self._send_output(message_body, encode_chunked=encode_chunked)
  File "c:\users\lenovo\appdata\local\programs\python\python38\lib\http\client.py", line 1010, in _send_output
    self.send(msg)
  File "c:\users\lenovo\appdata\local\programs\python\python38\lib\http\client.py", line 950, in send
    self.connect()
  File "G:\Care24\cms_backend\venv\lib\site-packages\urllib3\connection.py", line 200, in connect
    conn = self._new_conn()
  File "G:\Care24\cms_backend\venv\lib\site-packages\urllib3\connection.py", line 181, in _new_conn
    raise NewConnectionError(
urllib3.exceptions.NewConnectionError: <urllib3.connection.HTTPConnection object at 0x00000260DA5D8A00>: Failed to establish a new connection: [Errno 11001] getaddrinfo failed

During handling of the above exception, another exception occurred:

Traceback (most recent call last):
  File "G:\Care24\cms_backend\venv\lib\site-packages\requests\adapters.py", line 439, in send
    resp = conn.urlopen(
  File "G:\Care24\cms_backend\venv\lib\site-packages\urllib3\connectionpool.py", line 755, in urlopen
    retries = retries.increment(
  File "G:\Care24\cms_backend\venv\lib\site-packages\urllib3\util\retry.py", line 574, in increment
    raise MaxRetryError(_pool, url, error or ResponseError(cause))
urllib3.exceptions.MaxRetryError: HTTPConnectionPool(host='testserver', port=80): Max retries exceeded with url: /api-token-auth/ (Caused by NewConnectionError('<urllib3.connection.HTTPConnection object at 0x00000260DA5D8A00>: Failed to establish a new connection: [Errno 11001] getaddrinfo failed'))

During handling of the above exception, another exception occurred:

Traceback (most recent call last):
  File "G:\Care24\cms_backend\cms\helpers.py", line 26, in login
    auth_token = shared.generate_auth_token(self, password=request_data.get("password"),
  File "G:\Care24\cms_backend\cms\shared.py", line 39, in generate_auth_token
    response = requests.post(settings.SERVER_PROTOCOLS + host + "/api-token-auth/",
  File "G:\Care24\cms_backend\venv\lib\site-packages\requests\api.py", line 119, in post
    return request('post', url, data=data, json=json, **kwargs)
  File "G:\Care24\cms_backend\venv\lib\site-packages\requests\api.py", line 61, in request
    return session.request(method=method, url=url, **kwargs)
  File "G:\Care24\cms_backend\venv\lib\site-packages\requests\sessions.py", line 542, in request
    resp = self.send(prep, **send_kwargs)
  File "G:\Care24\cms_backend\venv\lib\site-packages\requests\sessions.py", line 655, in send
    r = adapter.send(request, **kwargs)
  File "G:\Care24\cms_backend\venv\lib\site-packages\requests\adapters.py", line 516, in send
    raise ConnectionError(e, request=request)
requests.exceptions.ConnectionError: HTTPConnectionPool(host='testserver', port=80): Max retries exceeded with url: /api-token-auth/ (Caused by NewConnectionError('<urllib3.connection.HTTPConnection object at 0x00000260DA5D8A00>: Failed to establish a new connection: [Errno 11001] getaddrinfo failed'))
[2021-03-28 21:04:40] INFO Registration  Api Service  Started
[2021-03-28 21:04:40] INFO Registration ended....
[2021-03-28 21:04:40] INFO {'status': False, 'data': {'message': 'Invalid Request'}}
[2021-03-28 21:04:40] INFO Registration  Api Service  Started
[2021-03-28 21:04:40] INFO Registration ended....
[2021-03-28 21:04:40] INFO {'status': True, 'data': {'message': 'User registered successfully.', 'status_code': 15}}
[2021-03-28 21:04:51] INFO Registration  Api Service  Started
[2021-03-28 21:04:51] INFO Registration ended....
[2021-03-28 21:04:51] INFO {'status': False, 'data': {'message': 'Invalid Request'}}
[2021-03-28 21:04:51] INFO Registration  Api Service  Started
[2021-03-28 21:04:51] INFO Registration ended....
[2021-03-28 21:04:51] INFO {'status': True, 'data': {'message': 'User registered successfully.', 'status_code': 15}}
[2021-03-28 21:05:34] INFO Registration  Api Service  Started
[2021-03-28 21:05:34] INFO Registration ended....
[2021-03-28 21:05:34] INFO {'status': False, 'data': {'message': 'Invalid Request'}}
[2021-03-28 21:05:34] INFO Registration  Api Service  Started
[2021-03-28 21:05:35] INFO Registration ended....
[2021-03-28 21:05:35] INFO {'status': True, 'data': {'message': 'User registered successfully.', 'status_code': 15}}
[2021-03-28 21:05:46] INFO Registration  Api Service  Started
[2021-03-28 21:05:46] INFO Registration ended....
[2021-03-28 21:05:46] INFO {'status': False, 'data': {'message': 'Invalid Request'}}
[2021-03-28 21:05:46] INFO Registration  Api Service  Started
[2021-03-28 21:05:46] INFO Registration ended....
[2021-03-28 21:05:46] INFO {'status': True, 'data': {'message': 'User registered successfully.', 'status_code': 15}}
[2021-03-28 21:06:08] INFO Registration  Api Service  Started
[2021-03-28 21:06:08] INFO Registration ended....
[2021-03-28 21:06:08] INFO {'status': True, 'data': {'message': 'User registered successfully.', 'status_code': 15}}
[2021-03-28 21:06:08] INFO login  Api Service  Started
[2021-03-28 21:06:10] ERROR HTTPConnectionPool(host='testserver', port=80): Max retries exceeded with url: /api-token-auth/ (Caused by NewConnectionError('<urllib3.connection.HTTPConnection object at 0x000001FB6EADFAF0>: Failed to establish a new connection: [Errno 11001] getaddrinfo failed'))
[2021-03-28 21:06:10] ERROR Exception raised in Login as HTTPConnectionPool(host='testserver', port=80): Max retries exceeded with url: /api-token-auth/ (Caused by NewConnectionError('<urllib3.connection.HTTPConnection object at 0x000001FB6EADFAF0>: Failed to establish a new connection: [Errno 11001] getaddrinfo failed'))
Traceback (most recent call last):
  File "G:\Care24\cms_backend\venv\lib\site-packages\urllib3\connection.py", line 169, in _new_conn
    conn = connection.create_connection(
  File "G:\Care24\cms_backend\venv\lib\site-packages\urllib3\util\connection.py", line 73, in create_connection
    for res in socket.getaddrinfo(host, port, family, socket.SOCK_STREAM):
  File "c:\users\lenovo\appdata\local\programs\python\python38\lib\socket.py", line 918, in getaddrinfo
    for res in _socket.getaddrinfo(host, port, family, type, proto, flags):
socket.gaierror: [Errno 11001] getaddrinfo failed

During handling of the above exception, another exception occurred:

Traceback (most recent call last):
  File "G:\Care24\cms_backend\venv\lib\site-packages\urllib3\connectionpool.py", line 699, in urlopen
    httplib_response = self._make_request(
  File "G:\Care24\cms_backend\venv\lib\site-packages\urllib3\connectionpool.py", line 394, in _make_request
    conn.request(method, url, **httplib_request_kw)
  File "G:\Care24\cms_backend\venv\lib\site-packages\urllib3\connection.py", line 234, in request
    super(HTTPConnection, self).request(method, url, body=body, headers=headers)
  File "c:\users\lenovo\appdata\local\programs\python\python38\lib\http\client.py", line 1255, in request
    self._send_request(method, url, body, headers, encode_chunked)
  File "c:\users\lenovo\appdata\local\programs\python\python38\lib\http\client.py", line 1301, in _send_request
    self.endheaders(body, encode_chunked=encode_chunked)
  File "c:\users\lenovo\appdata\local\programs\python\python38\lib\http\client.py", line 1250, in endheaders
    self._send_output(message_body, encode_chunked=encode_chunked)
  File "c:\users\lenovo\appdata\local\programs\python\python38\lib\http\client.py", line 1010, in _send_output
    self.send(msg)
  File "c:\users\lenovo\appdata\local\programs\python\python38\lib\http\client.py", line 950, in send
    self.connect()
  File "G:\Care24\cms_backend\venv\lib\site-packages\urllib3\connection.py", line 200, in connect
    conn = self._new_conn()
  File "G:\Care24\cms_backend\venv\lib\site-packages\urllib3\connection.py", line 181, in _new_conn
    raise NewConnectionError(
urllib3.exceptions.NewConnectionError: <urllib3.connection.HTTPConnection object at 0x000001FB6EADFAF0>: Failed to establish a new connection: [Errno 11001] getaddrinfo failed

During handling of the above exception, another exception occurred:

Traceback (most recent call last):
  File "G:\Care24\cms_backend\venv\lib\site-packages\requests\adapters.py", line 439, in send
    resp = conn.urlopen(
  File "G:\Care24\cms_backend\venv\lib\site-packages\urllib3\connectionpool.py", line 755, in urlopen
    retries = retries.increment(
  File "G:\Care24\cms_backend\venv\lib\site-packages\urllib3\util\retry.py", line 574, in increment
    raise MaxRetryError(_pool, url, error or ResponseError(cause))
urllib3.exceptions.MaxRetryError: HTTPConnectionPool(host='testserver', port=80): Max retries exceeded with url: /api-token-auth/ (Caused by NewConnectionError('<urllib3.connection.HTTPConnection object at 0x000001FB6EADFAF0>: Failed to establish a new connection: [Errno 11001] getaddrinfo failed'))

During handling of the above exception, another exception occurred:

Traceback (most recent call last):
  File "G:\Care24\cms_backend\cms\helpers.py", line 26, in login
    auth_token = shared.generate_auth_token(self, password=request_data.get("password"),
  File "G:\Care24\cms_backend\cms\shared.py", line 39, in generate_auth_token
    response = requests.post(settings.SERVER_PROTOCOLS + host + "/api-token-auth/",
  File "G:\Care24\cms_backend\venv\lib\site-packages\requests\api.py", line 119, in post
    return request('post', url, data=data, json=json, **kwargs)
  File "G:\Care24\cms_backend\venv\lib\site-packages\requests\api.py", line 61, in request
    return session.request(method=method, url=url, **kwargs)
  File "G:\Care24\cms_backend\venv\lib\site-packages\requests\sessions.py", line 542, in request
    resp = self.send(prep, **send_kwargs)
  File "G:\Care24\cms_backend\venv\lib\site-packages\requests\sessions.py", line 655, in send
    r = adapter.send(request, **kwargs)
  File "G:\Care24\cms_backend\venv\lib\site-packages\requests\adapters.py", line 516, in send
    raise ConnectionError(e, request=request)
requests.exceptions.ConnectionError: HTTPConnectionPool(host='testserver', port=80): Max retries exceeded with url: /api-token-auth/ (Caused by NewConnectionError('<urllib3.connection.HTTPConnection object at 0x000001FB6EADFAF0>: Failed to establish a new connection: [Errno 11001] getaddrinfo failed'))
[2021-03-28 21:06:11] INFO Registration  Api Service  Started
[2021-03-28 21:06:11] INFO Registration ended....
[2021-03-28 21:06:11] INFO {'status': False, 'data': {'message': 'Invalid Request'}}
[2021-03-28 21:06:11] INFO Registration  Api Service  Started
[2021-03-28 21:06:11] INFO Registration ended....
[2021-03-28 21:06:11] INFO {'status': True, 'data': {'message': 'User registered successfully.', 'status_code': 15}}
[2021-03-28 21:06:29] INFO Registration  Api Service  Started
[2021-03-28 21:06:30] INFO Registration ended....
[2021-03-28 21:06:30] INFO {'status': True, 'data': {'message': 'User registered successfully.', 'status_code': 15}}
[2021-03-28 21:06:30] INFO Registration  Api Service  Started
[2021-03-28 21:06:30] INFO Registration ended....
[2021-03-28 21:06:30] INFO {'status': False, 'data': {'message': 'Invalid Request'}}
[2021-03-28 21:06:30] INFO Registration  Api Service  Started
[2021-03-28 21:06:30] INFO Registration ended....
[2021-03-28 21:06:30] INFO {'status': True, 'data': {'message': 'User registered successfully.', 'status_code': 15}}
[2021-03-28 21:08:34] INFO Registration  Api Service  Started
[2021-03-28 21:08:34] INFO Registration ended....
[2021-03-28 21:08:34] INFO {'status': True, 'data': {'message': 'User registered successfully.', 'status_code': 15}}
[2021-03-28 21:08:35] INFO Registration  Api Service  Started
[2021-03-28 21:08:35] INFO Registration ended....
[2021-03-28 21:08:35] INFO {'status': True, 'data': {'message': 'User registered successfully.', 'status_code': 15}}
[2021-03-28 21:08:35] INFO Registration  Api Service  Started
[2021-03-28 21:08:35] INFO Registration ended....
[2021-03-28 21:08:35] INFO {'status': False, 'data': {'message': 'Invalid Request'}}
[2021-03-28 21:08:35] INFO Registration  Api Service  Started
[2021-03-28 21:08:36] INFO Registration ended....
[2021-03-28 21:08:36] INFO {'status': True, 'data': {'message': 'User registered successfully.', 'status_code': 15}}
[2021-03-28 21:08:46] INFO Registration  Api Service  Started
[2021-03-28 21:08:46] INFO Registration ended....
[2021-03-28 21:08:46] INFO {'status': True, 'data': {'message': 'User registered successfully.', 'status_code': 15}}
[2021-03-28 21:08:47] INFO Registration  Api Service  Started
[2021-03-28 21:08:47] INFO Registration ended....
[2021-03-28 21:08:47] INFO {'status': True, 'data': {'message': 'User registered successfully.', 'status_code': 15}}
[2021-03-28 21:08:47] INFO Registration  Api Service  Started
[2021-03-28 21:08:47] INFO Registration ended....
[2021-03-28 21:08:47] INFO {'status': False, 'data': {'message': 'Invalid Request'}}
[2021-03-28 21:08:47] INFO Registration  Api Service  Started
[2021-03-28 21:08:48] INFO Registration ended....
[2021-03-28 21:08:48] INFO {'status': True, 'data': {'message': 'User registered successfully.', 'status_code': 15}}
[2021-03-28 21:14:37] INFO Registration  Api Service  Started
[2021-03-28 21:14:38] INFO Registration ended....
[2021-03-28 21:14:38] INFO {'status': True, 'data': {'message': 'User registered successfully.', 'status_code': 15}}
[2021-03-28 21:14:38] INFO Registration  Api Service  Started
[2021-03-28 21:14:38] INFO Registration ended....
[2021-03-28 21:14:38] INFO {'status': False, 'data': {'message': 'Invalid Request'}}
[2021-03-28 21:14:38] INFO Registration  Api Service  Started
[2021-03-28 21:14:38] INFO Registration ended....
[2021-03-28 21:14:38] INFO {'status': True, 'data': {'message': 'User registered successfully.', 'status_code': 15}}
[2021-03-28 21:15:08] INFO Registration  Api Service  Started
[2021-03-28 21:15:09] INFO Registration ended....
[2021-03-28 21:15:09] INFO {'status': True, 'data': {'message': 'User registered successfully.', 'status_code': 15}}
[2021-03-28 21:15:09] INFO Registration  Api Service  Started
[2021-03-28 21:15:09] INFO Registration ended....
[2021-03-28 21:15:09] INFO {'status': False, 'data': {'message': 'Invalid Request'}}
[2021-03-28 21:15:09] INFO Registration  Api Service  Started
[2021-03-28 21:15:09] INFO Registration ended....
[2021-03-28 21:15:09] INFO {'status': True, 'data': {'message': 'User registered successfully.', 'status_code': 15}}
[2021-03-28 21:16:59] INFO Registration  Api Service  Started
[2021-03-28 21:16:59] INFO Registration ended....
[2021-03-28 21:16:59] INFO {'status': True, 'data': {'message': 'User registered successfully.', 'status_code': 15}}
[2021-03-28 21:16:59] INFO Registration  Api Service  Started
[2021-03-28 21:16:59] INFO Registration ended....
[2021-03-28 21:16:59] INFO {'status': False, 'data': {'message': 'Invalid Request'}}
[2021-03-28 21:16:59] INFO Registration  Api Service  Started
[2021-03-28 21:17:00] INFO Registration ended....
[2021-03-28 21:17:00] INFO {'status': True, 'data': {'message': 'User registered successfully.', 'status_code': 15}}
[2021-03-28 21:20:20] INFO Registration  Api Service  Started
[2021-03-28 21:20:21] INFO Registration ended....
[2021-03-28 21:20:21] INFO {'status': True, 'data': {'message': 'User registered successfully.', 'status_code': 15}}
[2021-03-28 21:20:21] INFO Registration  Api Service  Started
[2021-03-28 21:20:21] INFO Registration ended....
[2021-03-28 21:20:21] INFO {'status': False, 'data': {'message': 'Invalid Request'}}
[2021-03-28 21:20:21] INFO Registration  Api Service  Started
[2021-03-28 21:20:21] INFO Registration ended....
[2021-03-28 21:20:21] INFO {'status': True, 'data': {'message': 'User registered successfully.', 'status_code': 15}}
[2021-03-28 21:20:54] INFO Registration  Api Service  Started
[2021-03-28 21:20:54] INFO Registration ended....
[2021-03-28 21:20:54] INFO {'status': True, 'data': {'message': 'User registered successfully.', 'status_code': 15}}
[2021-03-28 21:20:55] INFO Registration  Api Service  Started
[2021-03-28 21:20:55] INFO Registration ended....
[2021-03-28 21:20:55] INFO {'status': False, 'data': {'message': 'Invalid Request'}}
[2021-03-28 21:20:55] INFO Registration  Api Service  Started
[2021-03-28 21:20:55] INFO Registration ended....
[2021-03-28 21:20:55] INFO {'status': True, 'data': {'message': 'User registered successfully.', 'status_code': 15}}
[2021-03-28 21:21:55] INFO Registration  Api Service  Started
[2021-03-28 21:21:55] INFO Registration ended....
[2021-03-28 21:21:55] INFO {'status': True, 'data': {'message': 'User registered successfully.', 'status_code': 15}}
[2021-03-28 21:21:55] INFO Registration  Api Service  Started
[2021-03-28 21:21:55] INFO Registration ended....
[2021-03-28 21:21:55] INFO {'status': False, 'data': {'message': 'Invalid Request'}}
[2021-03-28 21:21:55] INFO Registration  Api Service  Started
[2021-03-28 21:21:56] INFO Registration ended....
[2021-03-28 21:21:56] INFO {'status': True, 'data': {'message': 'User registered successfully.', 'status_code': 15}}
